Workbook

Sheet Data
A1: battery_id | B1: chemistry | C1: nominal_voltage_V | D1: rated_capacity_Ah | E1: state_of_charge_percent | F1: state_of_health_percent | G1: temperature_C | H1: internal_resistance_mOhm | I1: cycle_count | J1: age_years | K1: cell_voltage_imbalance_mV | L1: max_temperature_last_24h_C | M1: estimated_available_energy_kWh | N1: station_status | O1: hard_cutoff_status | P1: composite_risk_score | Q1: risk_tier | R1: isolate_trigger_reason
A2: BAT-001 | B2: LFP | C2: 48 | D2: 40 | E2: 73.2 | F2: 81.4 | G2: 30.4 | H2: 50.3 | I2: 1080 | J2: 0.78 | K2: 56.9 | L2: 36.6 | M2: 1.144 | N2: AVAILABLE | O2: =IF(OR(F2<Thresholds!$B$6,H2>=Thresholds!$B$7,K2>=Thresholds!$B$9,L2>Thresholds!$B$11,G2>Thresholds!$B$10),"ISOLATE",IF(AND(F2>=Thresholds!$B$5,K2<=Thresholds!$B$8),"SAFE","DEGRADE/USE")) -> DEGRADE/USE | P2: =Thresholds!$B$14*MIN(100-F2,40)/40+Thresholds!$B$15*MIN(H2,90)/90+Thresholds!$B$16*MIN(K2,100)/100+Thresholds!$B$17*MIN(I2,1600)/1600+Thresholds!$B$18*MIN(J2,5)/5+Thresholds!$B$19*MAX(0,G2-25)/25 -> 50.237222 | Q2: =IF(P2>Thresholds!$B$13,"High Risk",IF(P2>Thresholds!$B$12,"Moderate Risk","Low Risk")) -> Moderate Risk | R2: =TRIM(IF(F2<Thresholds!$B$6,"Low SOH; ","")&IF(H2>=Thresholds!$B$7,"High IR; ","")&IF(K2>=Thresholds!$B$9,"High Imbalance; ","")&IF(L2>Thresholds!$B$11,"Sustained Heat 24h; ","")&IF(G2>Thresholds!$B$10,"High Temp; ",""))
A3: BAT-002 | B3: LFP | C3: 48 | D3: 40 | E3: 62 | F3: 88.9 | G3: 26.8 | H3: 52.2 | I3: 231 | J3: 1.47 | K3: 23.1 | L3: 28.6 | M3: 1.059 | N3: AVAILABLE | O3: =IF(OR(F3<Thresholds!$B$6,H3>=Thresholds!$B$7,K3>=Thresholds!$B$9,L3>Thresholds!$B$11,G3>Thresholds!$B$10),"ISOLATE",IF(AND(F3>=Thresholds!$B$5,K3<=Thresholds!$B$8),"SAFE","DEGRADE/USE")) -> SAFE | P3: =Thresholds!$B$14*MIN(100-F3,40)/40+Thresholds!$B$15*MIN(H3,90)/90+Thresholds!$B$16*MIN(K3,100)/100+Thresholds!$B$17*MIN(I3,1600)/1600+Thresholds!$B$18*MIN(J3,5)/5+Thresholds!$B$19*MAX(0,G3-25)/25 -> 32.10625 | Q3: =IF(P3>Thresholds!$B$13,"High Risk",IF(P3>Thresholds!$B$12,"Moderate Risk","Low Risk")) -> Low Risk | R3: =TRIM(IF(F3<Thresholds!$B$6,"Low SOH; ","")&IF(H3>=Thresholds!$B$7,"High IR; ","")&IF(K3>=Thresholds!$B$9,"High Imbalance; ","")&IF(L3>Thresholds!$B$11,"Sustained Heat 24h; ","")&IF(G3>Thresholds!$B$10,"High Temp; ",""))
A4: BAT-003 | B4: LFP | C4: 48 | D4: 40 | E4: 77.5 | F4: 69 | G4: 21.4 | H4: 68.7 | I4: 1317 | J4: 3.82 | K4: 67.6 | L4: 26.5 | M4: 1.027 | N4: AVAILABLE | O4: =IF(OR(F4<Thresholds!$B$6,H4>=Thresholds!$B$7,K4>=Thresholds!$B$9,L4>Thresholds!$B$11,G4>Thresholds!$B$10),"ISOLATE",IF(AND(F4>=Thresholds!$B$5,K4<=Thresholds!$B$8),"SAFE","DEGRADE/USE")) -> DEGRADE/USE | P4: =Thresholds!$B$14*MIN(100-F4,40)/40+Thresholds!$B$15*MIN(H4,90)/90+Thresholds!$B$16*MIN(K4,100)/100+Thresholds!$B$17*MIN(I4,1600)/1600+Thresholds!$B$18*MIN(J4,5)/5+Thresholds!$B$19*MAX(0,G4-25)/25 -> 71.779583 | Q4: =IF(P4>Thresholds!$B$13,"High Risk",IF(P4>Thresholds!$B$12,"Moderate Risk","Low Risk")) -> High Risk | R4: =TRIM(IF(F4<Thresholds!$B$6,"Low SOH; ","")&IF(H4>=Thresholds!$B$7,"High IR; ","")&IF(K4>=Thresholds!$B$9,"High Imbalance; ","")&IF(L4>Thresholds!$B$11,"Sustained Heat 24h; ","")&IF(G4>Thresholds!$B$10,"High Temp; ",""))
A5: BAT-004 | B5: LFP | C5: 48 | D5: 40 | E5: 85.6 | F5: 82.8 | G5: 35.3 | H5: 64.7 | I5: 442 | J5: 4.26 | K5: 42.5 | L5: 42.1 | M5: 1.362 | N5: AVAILABLE | O5: =IF(OR(F5<Thresholds!$B$6,H5>=Thresholds!$B$7,K5>=Thresholds!$B$9,L5>Thresholds!$B$11,G5>Thresholds!$B$10),"ISOLATE",IF(AND(F5>=Thresholds!$B$5,K5<=Thresholds!$B$8),"SAFE","DEGRADE/USE")) -> SAFE | P5: =Thresholds!$B$14*MIN(100-F5,40)/40+Thresholds!$B$15*MIN(H5,90)/90+Thresholds!$B$16*MIN(K5,100)/100+Thresholds!$B$17*MIN(I5,1600)/1600+Thresholds!$B$18*MIN(J5,5)/5+Thresholds!$B$19*MAX(0,G5-25)/25 -> 50.604722 | Q5: =IF(P5>Thresholds!$B$13,"High Risk",IF(P5>Thresholds!$B$12,"Moderate Risk","Low Risk")) -> Moderate Risk | R5: =TRIM(IF(F5<Thresholds!$B$6,"Low SOH; ","")&IF(H5>=Thresholds!$B$7,"High IR; ","")&IF(K5>=Thresholds!$B$9,"High Imbalance; ","")&IF(L5>Thresholds!$B$11,"Sustained Heat 24h; ","")&IF(G5>Thresholds!$B$10,"High Temp; ",""))
A6: BAT-005 | B6: LFP | C6: 48 | D6: 40 | E6: 58.8 | F6: 80 | G6: 23.1 | H6: 55 | I6: 1078 | J6: 0.94 | K6: 50.4 | L6: 25.9 | M6: 0.903 | N6: AVAILABLE | O6: =IF(OR(F6<Thresholds!$B$6,H6>=Thresholds!$B$7,K6>=Thresholds!$B$9,L6>Thresholds!$B$11,G6>Thresholds!$B$10),"ISOLATE",IF(AND(F6>=Thresholds!$B$5,K6<=Thresholds!$B$8),"SAFE","DEGRADE/USE")) -> DEGRADE/USE | P6: =Thresholds!$B$14*MIN(100-F6,40)/40+Thresholds!$B$15*MIN(H6,90)/90+Thresholds!$B$16*MIN(K6,100)/100+Thresholds!$B$17*MIN(I6,1600)/1600+Thresholds!$B$18*MIN(J6,5)/5+Thresholds!$B$19*MAX(0,G6-25)/25 -> 50.535278 | Q6: =IF(P6>Thresholds!$B$13,"High Risk",IF(P6>Thresholds!$B$12,"Moderate Risk","Low Risk")) -> Moderate Risk | R6: =TRIM(IF(F6<Thresholds!$B$6,"Low SOH; ","")&IF(H6>=Thresholds!$B$7,"High IR; ","")&IF(K6>=Thresholds!$B$9,"High Imbalance; ","")&IF(L6>Thresholds!$B$11,"Sustained Heat 24h; ","")&IF(G6>Thresholds!$B$10,"High Temp; ",""))
A7: BAT-006 | B7: LFP | C7: 48 | D7: 40 | E7: 81.4 | F7: 75.8 | G7: 29.3 | H7: 57.1 | I7: 673 | J7: 3.58 | K7: 75 | L7: 33.5 | M7: 1.185 | N7: AVAILABLE | O7: =IF(OR(F7<Thresholds!$B$6,H7>=Thresholds!$B$7,K7>=Thresholds!$B$9,L7>Thresholds!$B$11,G7>Thresholds!$B$10),"ISOLATE",IF(AND(F7>=Thresholds!$B$5,K7<=Thresholds!$B$8),"SAFE","DEGRADE/USE")) -> DEGRADE/USE | P7: =Thresholds!$B$14*MIN(100-F7,40)/40+Thresholds!$B$15*MIN(H7,90)/90+Thresholds!$B$16*MIN(K7,100)/100+Thresholds!$B$17*MIN(I7,1600)/1600+Thresholds!$B$18*MIN(J7,5)/5+Thresholds!$B$19*MAX(0,G7-25)/25 -> 60.682361 | Q7: =IF(P7>Thresholds!$B$13,"High Risk",IF(P7>Thresholds!$B$12,"Moderate Risk","Low Risk")) -> Moderate Risk | R7: =TRIM(IF(F7<Thresholds!$B$6,"Low SOH; ","")&IF(H7>=Thresholds!$B$7,"High IR; ","")&IF(K7>=Thresholds!$B$9,"High Imbalance; ","")&IF(L7>Thresholds!$B$11,"Sustained Heat 24h; ","")&IF(G7>Thresholds!$B$10,"High Temp; ",""))
A8: BAT-007 | B8: LFP | C8: 48 | D8: 40 | E8: 49 | F8: 95 | G8: 38.1 | H8: 33.6 | I8: 177 | J8: 1.76 | K8: 12 | L8: 38.7 | M8: 0.895 | N8: AVAILABLE | O8: =IF(OR(F8<Thresholds!$B$6,H8>=Thresholds!$B$7,K8>=Thresholds!$B$9,L8>Thresholds!$B$11,G8>Thresholds!$B$10),"ISOLATE",IF(AND(F8>=Thresholds!$B$5,K8<=Thresholds!$B$8),"SAFE","DEGRADE/USE")) -> SAFE | P8: =Thresholds!$B$14*MIN(100-F8,40)/40+Thresholds!$B$15*MIN(H8,90)/90+Thresholds!$B$16*MIN(K8,100)/100+Thresholds!$B$17*MIN(I8,1600)/1600+Thresholds!$B$18*MIN(J8,5)/5+Thresholds!$B$19*MAX(0,G8-25)/25 -> 21.594583 | Q8: =IF(P8>Thresholds!$B$13,"High Risk",IF(P8>Thresholds!$B$12,"Moderate Risk","Low Risk")) -> Low Risk | R8: =TRIM(IF(F8<Thresholds!$B$6,"Low SOH; ","")&IF(H8>=Thresholds!$B$7,"High IR; ","")&IF(K8>=Thresholds!$B$9,"High Imbalance; ","")&IF(L8>Thresholds!$B$11,"Sustained Heat 24h; ","")&IF(G8>Thresholds!$B$10,"High Temp; ",""))
A9: BAT-008 | B9: LFP | C9: 48 | D9: 40 | E9: 99 | F9: 72 | G9: 49 | H9: 84 | I9: 1551 | J9: 1.08 | K9: 91 | L9: 43.2 | M9: 0.694 | N9: REVIEW/QUARANTINE | O9: =IF(OR(F9<Thresholds!$B$6,H9>=Thresholds!$B$7,K9>=Thresholds!$B$9,L9>Thresholds!$B$11,G9>Thresholds!$B$10),"ISOLATE",IF(AND(F9>=Thresholds!$B$5,K9<=Thresholds!$B$8),"SAFE","DEGRADE/USE")) -> ISOLATE | P9: =Thresholds!$B$14*MIN(100-F9,40)/40+Thresholds!$B$15*MIN(H9,90)/90+Thresholds!$B$16*MIN(K9,100)/100+Thresholds!$B$17*MIN(I9,1600)/1600+Thresholds!$B$18*MIN(J9,5)/5+Thresholds!$B$19*MAX(0,G9-25)/25 -> 81.607083 | Q9: =IF(P9>Thresholds!$B$13,"High Risk",IF(P9>Thresholds!$B$12,"Moderate Risk","Low Risk")) -> High Risk | R9: =TRIM(IF(F9<Thresholds!$B$6,"Low SOH; ","")&IF(H9>=Thresholds!$B$7,"High IR; ","")&IF(K9>=Thresholds!$B$9,"High Imbalance; ","")&IF(L9>Thresholds!$B$11,"Sustained Heat 24h; ","")&IF(G9>Thresholds!$B$10,"High Temp; ","")) -> High IR; High Imbalance; High Temp;
A10: BAT-009 | B10: LFP | C10: 48 | D10: 40 | E10: 83 | F10: 78.7 | G10: 33 | H10: 62.8 | I10: 874 | J10: 0.67 | K10: 60.4 | L10: 34.2 | M10: 1.255 | N10: AVAILABLE | O10: =IF(OR(F10<Thresholds!$B$6,H10>=Thresholds!$B$7,K10>=Thresholds!$B$9,L10>Thresholds!$B$11,G10>Thresholds!$B$10),"ISOLATE",IF(AND(F10>=Thresholds!$B$5,K10<=Thresholds!$B$8),"SAFE","DEGRADE/USE")) -> DEGRADE/USE | P10: =Thresholds!$B$14*MIN(100-F10,40)/40+Thresholds!$B$15*MIN(H10,90)/90+Thresholds!$B$16*MIN(K10,100)/100+Thresholds!$B$17*MIN(I10,1600)/1600+Thresholds!$B$18*MIN(J10,5)/5+Thresholds!$B$19*MAX(0,G10-25)/25 -> 55.894444 | Q10: =IF(P10>Thresholds!$B$13,"High Risk",IF(P10>Thresholds!$B$12,"Moderate Risk","Low Risk")) -> Moderate Risk | R10: =TRIM(IF(F10<Thresholds!$B$6,"Low SOH; ","")&IF(H10>=Thresholds!$B$7,"High IR; ","")&IF(K10>=Thresholds!$B$9,"High Imbalance; ","")&IF(L10>Thresholds!$B$11,"Sustained Heat 24h; ","")&IF(G10>Thresholds!$B$10,"High Temp; ",""))
A11: BAT-010 | B11: LFP | C11: 48 | D11: 40 | E11: 67.7 | F11: 96 | G11: 23.5 | H11: 45.5 | I11: 293 | J11: 0.67 | K11: 19.3 | L11: 30.1 | M11: 1.247 | N11: AVAILABLE | O11: =IF(OR(F11<Thresholds!$B$6,H11>=Thresholds!$B$7,K11>=Thresholds!$B$9,L11>Thresholds!$B$11,G11>Thresholds!$B$10),"ISOLATE",IF(AND(F11>=Thresholds!$B$5,K11<=Thresholds!$B$8),"SAFE","DEGRADE/USE")) -> SAFE | P11: =Thresholds!$B$14*MIN(100-F11,40)/40+Thresholds!$B$15*MIN(H11,90)/90+Thresholds!$B$16*MIN(K11,100)/100+Thresholds!$B$17*MIN(I11,1600)/1600+Thresholds!$B$18*MIN(J11,5)/5+Thresholds!$B$19*MAX(0,G11-25)/25 -> 22.500139 | Q11: =IF(P11>Thresholds!$B$13,"High Risk",IF(P11>Thresholds!$B$12,"Moderate Risk","Low Risk")) -> Low Risk | R11: =TRIM(IF(F11<Thresholds!$B$6,"Low SOH; ","")&IF(H11>=Thresholds!$B$7,"High IR; ","")&IF(K11>=Thresholds!$B$9,"High Imbalance; ","")&IF(L11>Thresholds!$B$11,"Sustained Heat 24h; ","")&IF(G11>Thresholds!$B$10,"High Temp; ",""))
A12: BAT-011 | B12: LFP | C12: 48 | D12: 40 | E12: 55.9 | F12: 71.6 | G12: 30.9 | H12: 64.5 | I12: 1590 | J12: 2.42 | K12: 55.9 | L12: 35.3 | M12: 0.768 | N12: AVAILABLE | O12: =IF(OR(F12<Thresholds!$B$6,H12>=Thresholds!$B$7,K12>=Thresholds!$B$9,L12>Thresholds!$B$11,G12>Thresholds!$B$10),"ISOLATE",IF(AND(F12>=Thresholds!$B$5,K12<=Thresholds!$B$8),"SAFE","DEGRADE/USE")) -> DEGRADE/USE | P12: =Thresholds!$B$14*MIN(100-F12,40)/40+Thresholds!$B$15*MIN(H12,90)/90+Thresholds!$B$16*MIN(K12,100)/100+Thresholds!$B$17*MIN(I12,1600)/1600+Thresholds!$B$18*MIN(J12,5)/5+Thresholds!$B$19*MAX(0,G12-25)/25 -> 67.484167 | Q12: =IF(P12>Thresholds!$B$13,"High Risk",IF(P12>Thresholds!$B$12,"Moderate Risk","Low Risk")) -> High Risk | R12: =TRIM(IF(F12<Thresholds!$B$6,"Low SOH; ","")&IF(H12>=Thresholds!$B$7,"High IR; ","")&IF(K12>=Thresholds!$B$9,"High Imbalance; ","")&IF(L12>Thresholds!$B$11,"Sustained Heat 24h; ","")&IF(G12>Thresholds!$B$10,"High Temp; ",""))
A13: BAT-012 | B13: LFP | C13: 48 | D13: 40 | E13: 79 | F13: 76.3 | G13: 31.9 | H13: 73 | I13: 1377 | J13: 0.76 | K13: 49.7 | L13: 34.5 | M13: 1.158 | N13: AVAILABLE | O13: =IF(OR(F13<Thresholds!$B$6,H13>=Thresholds!$B$7,K13>=Thresholds!$B$9,L13>Thresholds!$B$11,G13>Thresholds!$B$10),"ISOLATE",IF(AND(F13>=Thresholds!$B$5,K13<=Thresholds!$B$8),"SAFE","DEGRADE/USE")) -> DEGRADE/USE | P13: =Thresholds!$B$14*MIN(100-F13,40)/40+Thresholds!$B$15*MIN(H13,90)/90+Thresholds!$B$16*MIN(K13,100)/100+Thresholds!$B$17*MIN(I13,1600)/1600+Thresholds!$B$18*MIN(J13,5)/5+Thresholds!$B$19*MAX(0,G13-25)/25 -> 61.701528 | Q13: =IF(P13>Thresholds!$B$13,"High Risk",IF(P13>Thresholds!$B$12,"Moderate Risk","Low Risk")) -> Moderate Risk | R13: =TRIM(IF(F13<Thresholds!$B$6,"Low SOH; ","")&IF(H13>=Thresholds!$B$7,"High IR; ","")&IF(K13>=Thresholds!$B$9,"High Imbalance; ","")&IF(L13>Thresholds!$B$11,"Sustained Heat 24h; ","")&IF(G13>Thresholds!$B$10,"High Temp; ",""))
... A201: BAT-200 | B201: LFP | C201: 48 | D201: 40 | E201: 81.8 | F201: 75 | G201: 23.3 | H201: 63.7 | I201: 1032 | J201: 3.65 | K201: 55.1 | L201: 27.2 | M201: 1.179 | N201: AVAILABLE | O201: =IF(OR(F201<Thresholds!$B$6,H201>=Thresholds!$B$7,K201>=Thresholds!$B$9,L201>Thresholds!$B$11,G201>Thresholds!$B$10),"ISOLATE",IF(AND(F201>=Thresholds!$B$5,K201<=Thresholds!$B$8),"SAFE","DEGRADE/USE")) -> DEGRADE/USE | P201: =Thresholds!$B$14*MIN(100-F201,40)/40+Thresholds!$B$15*MIN(H201,90)/90+Thresholds!$B$16*MIN(K201,100)/100+Thresholds!$B$17*MIN(I201,1600)/1600+Thresholds!$B$18*MIN(J201,5)/5+Thresholds!$B$19*MAX(0,G201-25)/25 -> 60.689444 | Q201: =IF(P201>Thresholds!$B$13,"High Risk",IF(P201>Thresholds!$B$12,"Moderate Risk","Low Risk")) -> Moderate Risk | R201: =TRIM(IF(F201<Thresholds!$B$6,"Low SOH; ","")&IF(H201>=Thresholds!$B$7,"High IR; ","")&IF(K201>=Thresholds!$B$9,"High Imbalance; ","")&IF(L201>Thresholds!$B$11,"Sustained Heat 24h; ","")&IF(G201>Thresholds!$B$10,"High Temp; ",""))

Sheet Statistics
A1: Fleet Risk Statistics
A2: All values computed live via formulas against the Data sheet.
A4: 1. Risk Tier Counts (Hard Cutoff Status)
A5: Status | B5: Count | C5: % of Fleet
A6: SAFE | B6: =COUNTIF(Data!$O$2:$O$201,"SAFE") -> 84 | C6: =B6/200 -> 0.42
A7: DEGRADE/USE | B7: =COUNTIF(Data!$O$2:$O$201,"DEGRADE/USE") -> 91 | C7: =B7/200 -> 0.455
A8: ISOLATE | B8: =COUNTIF(Data!$O$2:$O$201,"ISOLATE") -> 25 | C8: =B8/200 -> 0.125
A9: Total | B9: =SUM(B6:B8) -> 200
A12: 2. Composite Risk Tier Counts
A13: Status | B13: Count | C13: % of Fleet
A14: Low Risk | B14: =COUNTIF(Data!$Q$2:$Q$201,"Low Risk") -> 36 | C14: =B14/200 -> 0.18
A15: Moderate Risk | B15: =COUNTIF(Data!$Q$2:$Q$201,"Moderate Risk") -> 110 | C15: =B15/200 -> 0.55
A16: High Risk | B16: =COUNTIF(Data!$Q$2:$Q$201,"High Risk") -> 54 | C16: =B16/200 -> 0.27
A19: 3. Cross-check: Hard Cutoff Status vs Original station_status
B20: AVAILABLE | C20: REVIEW/QUARANTINE | D20: Total
A21: SAFE | B21: =COUNTIFS(Data!$O$2:$O$201,"SAFE",Data!$N$2:$N$201,"AVAILABLE") -> 84 | C21: =COUNTIFS(Data!$O$2:$O$201,"SAFE",Data!$N$2:$N$201,"REVIEW/QUARANTINE") -> 0 | D21: =B21+C21 -> 84
A22: DEGRADE/USE | B22: =COUNTIFS(Data!$O$2:$O$201,"DEGRADE/USE",Data!$N$2:$N$201,"AVAILABLE") -> 89 | C22: =COUNTIFS(Data!$O$2:$O$201,"DEGRADE/USE",Data!$N$2:$N$201,"REVIEW/QUARANTINE") -> 2 | D22: =B22+C22 -> 91
A23: ISOLATE | B23: =COUNTIFS(Data!$O$2:$O$201,"ISOLATE",Data!$N$2:$N$201,"AVAILABLE") -> 15 | C23: =COUNTIFS(Data!$O$2:$O$201,"ISOLATE",Data!$N$2:$N$201,"REVIEW/QUARANTINE") -> 10 | D23: =B23+C23 -> 25
A24: Total | B24: =SUM(B21:B23) -> 188 | C24: =SUM(C21:C23) -> 12 | D24: =SUM(D21:D23) -> 200
A27: 4. Descriptive Statistics by Key Metric (whole fleet)
A28: Metric | B28: Mean | C28: Median | D28: Std Dev | E28: Min | F28: Max
A29: State of Health (%) | B29: =AVERAGE(Data!$F$2:$F$201) -> 80.067 | C29: =MEDIAN(Data!$F$2:$F$201) -> 80.1 | D29: =STDEV(Data!$F$2:$F$201) -> 9.3049569 | E29: =MIN(Data!$F$2:$F$201) -> 58 | F29: =MAX(Data!$F$2:$F$201) -> 100
A30: Internal Resistance (mOhm) | B30: =AVERAGE(Data!$H$2:$H$201) -> 60.946 | C30: =MEDIAN(Data!$H$2:$H$201) -> 60.7 | D30: =STDEV(Data!$H$2:$H$201) -> 11.383537 | E30: =MIN(Data!$H$2:$H$201) -> 33.6 | F30: =MAX(Data!$H$2:$H$201) -> 89.9
A31: Voltage Imbalance (mV) | B31: =AVERAGE(Data!$K$2:$K$201) -> 47.636 | C31: =MEDIAN(Data!$K$2:$K$201) -> 48.2 | D31: =STDEV(Data!$K$2:$K$201) -> 19.560529 | E31: =MIN(Data!$K$2:$K$201) -> 6.1 | F31: =MAX(Data!$K$2:$K$201) -> 118
A32: Temperature (C) | B32: =AVERAGE(Data!$G$2:$G$201) -> 31.4445 | C32: =MEDIAN(Data!$G$2:$G$201) -> 30.85 | D32: =STDEV(Data!$G$2:$G$201) -> 5.3379244 | E32: =MIN(Data!$G$2:$G$201) -> 18 | F32: =MAX(Data!$G$2:$G$201) -> 51
A33: Max Temp 24h (C) | B33: =AVERAGE(Data!$L$2:$L$201) -> 35.5155 | C33: =MEDIAN(Data!$L$2:$L$201) -> 36.05 | D33: =STDEV(Data!$L$2:$L$201) -> 5.6928333 | E33: =MIN(Data!$L$2:$L$201) -> 21.1 | F33: =MAX(Data!$L$2:$L$201) -> 53
A34: Cycle Count | B34: =AVERAGE(Data!$I$2:$I$201) -> 844.49 | C34: =MEDIAN(Data!$I$2:$I$201) -> 865.5 | D34: =STDEV(Data!$I$2:$I$201) -> 443.34253 | E34: =MIN(Data!$I$2:$I$201) -> 42 | F34: =MAX(Data!$I$2:$I$201) -> 1592
A35: Age (years) | B35: =AVERAGE(Data!$J$2:$J$201) -> 2.446 | C35: =MEDIAN(Data!$J$2:$J$201) -> 2.365 | D35: =STDEV(Data!$J$2:$J$201) -> 1.3822304 | E35: =MIN(Data!$J$2:$J$201) -> 0.23 | F35: =MAX(Data!$J$2:$J$201) -> 4.97
A36: State of Charge (%) | B36: =AVERAGE(Data!$E$2:$E$201) -> 73.693 | C36: =MEDIAN(Data!$E$2:$E$201) -> 74.75 | D36: =STDEV(Data!$E$2:$E$201) -> 18.467833 | E36: =MIN(Data!$E$2:$E$201) -> 25.2 | F36: =MAX(Data!$E$2:$E$201) -> 100
A37: Available Energy (kWh) | B37: =AVERAGE(Data!$M$2:$M$201) -> 1.125135 | C37: =MEDIAN(Data!$M$2:$M$201) -> 1.1325 | D37: =STDEV(Data!$M$2:$M$201) -> 0.30834086 | E37: =MIN(Data!$M$2:$M$201) -> 0.399 | F37: =MAX(Data!$M$2:$M$201) -> 1.892
A38: Composite Risk Score | B38: =AVERAGE(Data!$P$2:$P$201) -> 52.927332 | C38: =MEDIAN(Data!$P$2:$P$201) -> 51.719931 | D38: =STDEV(Data!$P$2:$P$201) -> 17.499913 | E38: =MIN(Data!$P$2:$P$201) -> 15.174028 | F38: =MAX(Data!$P$2:$P$201) -> 93.952778
A41: 5. Descriptive Statistics by Hard Cutoff Tier
A42: Metric | B42: SAFE (mean) | C42: DEGRADE/USE (mean) | D42: ISOLATE (mean)
A43: State of Health (%) | B43: =AVERAGEIFS(Data!$F$2:$F$201,Data!$O$2:$O$201,"SAFE") -> 88.061905 | C43: =AVERAGEIFS(Data!$F$2:$F$201,Data!$O$2:$O$201,"DEGRADE/USE") -> 74.102198 | D43: =AVERAGEIFS(Data!$F$2:$F$201,Data!$O$2:$O$201,"ISOLATE") -> 74.916
A44: Internal Resistance (mOhm) | B44: =AVERAGEIFS(Data!$H$2:$H$201,Data!$O$2:$O$201,"SAFE") -> 51.897619 | C44: =AVERAGEIFS(Data!$H$2:$H$201,Data!$O$2:$O$201,"DEGRADE/USE") -> 66.9 | D44: =AVERAGEIFS(Data!$H$2:$H$201,Data!$O$2:$O$201,"ISOLATE") -> 69.676
A45: Voltage Imbalance (mV) | B45: =AVERAGEIFS(Data!$K$2:$K$201,Data!$O$2:$O$201,"SAFE") -> 31.57619 | C45: =AVERAGEIFS(Data!$K$2:$K$201,Data!$O$2:$O$201,"DEGRADE/USE") -> 58.863736 | D45: =AVERAGEIFS(Data!$K$2:$K$201,Data!$O$2:$O$201,"ISOLATE") -> 60.728
A46: Cycle Count | B46: =AVERAGEIFS(Data!$I$2:$I$201,Data!$O$2:$O$201,"SAFE") -> 473.34524 | C46: =AVERAGEIFS(Data!$I$2:$I$201,Data!$O$2:$O$201,"DEGRADE/USE") -> 1110.3736 | D46: =AVERAGEIFS(Data!$I$2:$I$201,Data!$O$2:$O$201,"ISOLATE") -> 1123.72
A47: Age (years) | B47: =AVERAGEIFS(Data!$J$2:$J$201,Data!$O$2:$O$201,"SAFE") -> 2.1713095 | C47: =AVERAGEIFS(Data!$J$2:$J$201,Data!$O$2:$O$201,"DEGRADE/USE") -> 2.7268132 | D47: =AVERAGEIFS(Data!$J$2:$J$201,Data!$O$2:$O$201,"ISOLATE") -> 2.3468
A48: Composite Risk Score | B48: =AVERAGEIFS(Data!$P$2:$P$201,Data!$O$2:$O$201,"SAFE") -> 37.554889 | C48: =AVERAGEIFS(Data!$P$2:$P$201,Data!$O$2:$O$201,"DEGRADE/USE") -> 63.836053 | D48: =AVERAGEIFS(Data!$P$2:$P$201,Data!$O$2:$O$201,"ISOLATE") -> 64.870994
A51: 6. Correlation Matrix (Pearson r) -- key numeric features
...

Sheet Thresholds
A1: Risk Thresholds & Model Assumptions (LFP Battery Fleet)
A2: Blue cells are editable inputs. Data sheet formulas reference these cells directly.
A4: Parameter | B4: Value | C4: Used For | D4: Notes
A5: SOH_safe_min | B5: 80 | C5: Safe tier lower bound (SOH %) | D5: Industry-standard first-life EOL threshold
A6: SOH_isolate_max | B6: 60 | C6: Isolate trigger (SOH % below this) | D6: Common second-life retirement floor
A7: IR_isolate_min | B7: 78 | C7: Isolate trigger (IR mOhm at/above this) | D7: ~95th percentile of fleet; ~2x fresh-pack baseline
A8: Imbalance_safe_max | B8: 50 | C8: Safe tier upper bound (mV) | D8: Typical BMS warning threshold
A9: Imbalance_isolate_min | B9: 80 | C9: Isolate trigger (mV at/above this) | D9: LFP flat OCV curve makes imbalance more meaningful; consider raising to 100 for stricter LFP practice
A10: Temp_isolate_min | B10: 45 | C10: Isolate trigger (instant temp, C, above this) | D10: Relaxed from original 38C -- within normal LFP charge range (up to ~45-55C); LFP thermal runaway onset is far higher than NMC
A11: MaxTemp24h_isolate_min | B11: 45 | C11: Isolate trigger (24h max temp, C, above this) | D11: Flags a sustained heat event in the last 24h
A12: RiskScore_safe_max | B12: 35 | C12: Composite score upper bound for Low Risk | D12: Tunable -- calibrate against real failure/warranty data if available
A13: RiskScore_degrade_max | B13: 65 | C13: Composite score upper bound for Moderate Risk | D13: Above this = High Risk tier
A14: W_SOH | B14: 35 | C14: Composite score weight - SOH deviation | D14: Weights sum to 100; allocated by correlation strength with SOH in this fleet
A15: W_IR | B15: 25 | C15: Composite score weight - internal resistance | D15: r=-0.91 with SOH in this fleet
A16: W_IMB | B16: 20 | C16: Composite score weight - voltage imbalance | D16: r=-0.83 with SOH in this fleet
... A19: W_TEMP | B19: 5 | C19: Composite score weight - thermal stress above 25C baseline | D19: Minor weight; LFP is thermally tolerant
A21: Weight sum check (should = 100) | B21: =B14+B15+B16+B17+B18+B19 -> 100
